<?xml version='1.0'?>

<robot name="archerfish" xmlns:xacro="http://www.ros.org/wiki/xacro">
  
  <xacro:include filename="inertial_macros.xacro"/>
  <xacro:include filename="archerfish_robot.gazebo.xacro"/>
  
    <material name="white">
        <color rgba="1 1 1 1" />
    </material>

    <material name="orange">
        <color rgba="1 0.3 0.1 1"/>
    </material>

    <material name="blue">
        <color rgba="0.2 0.2 1 1"/>
    </material>

    <material name="black">
        <color rgba="0 0 0 1"/>
    </material>

    <material name="red">
        <color rgba="1 0 0 1"/>
    </material>

    <link name="base_footprint"/>

    <joint name="base_joint" type="fixed">
        <parent link="base_footprint"/>
        <child link="base_link"/>
        <origin xyz="0 0 0.001"/>
    </joint>
    
    <link name="base_link">
        <visual>
          <origin xyz="0 0 0.001"/>
          <geometry>
              <cylinder length="0.1" radius="0.5"/>
          </geometry>
          <material name="white"/>
        </visual>
        <collision>
          <origin xyz="0 0 0.001"/>
          <geometry>
              <cylinder length="0.1" radius="0.5"/>
          </geometry>
        </collision>
        <xacro:inertial_cylinder mass="10" length="0.1" radius="0.5">
            <origin xyz="0 0 0.001" rpy="0 0 0"/>
        </xacro:inertial_cylinder>
    </link>
    
    <gazebo reference="base_link">
        <material>Gazebo/Black</material>
    </gazebo>
    
    <joint name="revolutejoint" type="continuous">
        <parent link="base_link"/>
        <child link="main_body"/>
        <origin xyz="0 0 0.001" rpy="-${pi/2} 0 0" />
        <axis xyz="0 1 0"/>
    </joint>

    <link name="main_body">
        <visual>
          <origin xyz="0 0 0.001"/>
          <geometry>
              <cylinder length="0.1" radius="0.5"/>
          </geometry>
          <material name="white"/>
        </visual>
        <xacro:inertial_cylinder mass="10" length="0.1" radius="0.5">
            <origin xyz="0 0 0.001" rpy="-${pi/2} 0 0"/>
        </xacro:inertial_cylinder>
    </link>

    <gazebo reference="main_body">
        <material>Gazebo/White</material>
    </gazebo>
    
    <joint name="aimjoint" type="continuous">
        <parent link="main_body"/>
        <child link="barrel"/>
        <origin xyz="0 0 0" rpy="0 -${pi/2} 0" />
        <axis xyz="1 0 0"/>
    </joint>

    <link name="barrel">
        <visual>
          <origin xyz="0 0 0.6"/>
          <geometry>
              <cylinder length="0.2" radius="0.05"/>
          </geometry>
          <material name="red"/>
        </visual>
        <xacro:inertial_cylinder mass="10" length="0.2" radius="0.05">
            <origin xyz="0 0 0.6" rpy="-${pi/2} -${pi/2} 0"/>
        </xacro:inertial_cylinder>
    </link>

    <gazebo reference="barrel">
        <material>Gazebo/Red</material>
    </gazebo>
    
    <joint name="camera_joint" type="fixed">
        <parent link="barrel"/>
        <child link="camera_link"/>
        <origin xyz="0 -0.05 0.6" rpy="0 -${pi/2} ${pi/2}"/>
    </joint>

    <link name="camera_link">
        <visual>
          <origin xyz="0 0 0"/>
          <geometry>
              <box size="0.1 0.1 0.05"/>
          </geometry>
          <material name="orange"/>
        </visual>
        <xacro:inertial_box mass="15" x="0.1" y="0.1" z="0.05">
            <origin xyz="0 0 0" rpy="0 0 0"/>
        </xacro:inertial_box>
    </link>

    <gazebo reference="camera_link">
        <material>Gazebo/Orange</material>
    </gazebo>
    
  <joint name="imu_joint" type="fixed">
    <parent link="base_link"/>
    <child link="imu_link"/>
    <origin xyz="-0.032 0 0.068" rpy="0 0 0"/>
  </joint>

  <link name="imu_link"/>
  
  <transmission name="tran1">
    <type>transmission_interface/SimpleTransmission</type>
    <joint name="aimjoint">
      <hardwareInterface>hardware_interface/EffortJointInterface</hardwareInterface>
    </joint>
    <actuator name="motor1">
      <hardwareInterface>hardware_interface/EffortJointInterface</hardwareInterface>
      <mechanicalReduction>1</mechanicalReduction>
    </actuator>
  </transmission>
  
  <transmission name="tran2">
    <type>transmission_interface/SimpleTransmission</type>
    <joint name="revolutejoint">
      <hardwareInterface>hardware_interface/EffortJointInterface</hardwareInterface>
    </joint>
    <actuator name="motor2">
      <hardwareInterface>hardware_interface/EffortJointInterface</hardwareInterface>
      <mechanicalReduction>1</mechanicalReduction>
    </actuator>
  </transmission>
    
</robot>
